Workbook

Sheet Dashboard
A1: PT ARUNIKA GROWTH INDONESIA — RECRUITMENT DASHBOARD | 2026
A2: Human Resources Division | Customer Experience & Digital Service Startup | Jakarta
B4: OPEN POSITION | D4: TOTAL KANDIDAT | F4: ON PROCESS (Interview) | H4: OFFERING STAGE | J4: HIRED BULAN INI | L4: REJECTED / WITHDRAW | N4: CONVERSION RATE | P4: AVG TIME TO HIRE (hr)
B5: =COUNTIF('Pipeline Rekrutmen'!E:E,"Open") | D5: =COUNTA('Pipeline Rekrutmen'!A4:A200)-1 | F5: =COUNTIF('Pipeline Rekrutmen'!H:H,"Interview User")+COUNTIF('Pipeline Rekrutmen'!H:H,"Interview HR") | H5: =COUNTIF('Pipeline Rekrutmen'!H:H,"Offering") | J5: =COUNTIF('Pipeline Rekrutmen'!H:H,"Hired") | L5: =COUNTIF('Pipeline Rekrutmen'!H:H,"Rejected")+COUNTIF('Pipeline Rekrutmen'!H:H,"Withdraw") | N5: =IFERROR(COUNTIF('Pipeline Rekrutmen'!H:H,"Hired")/(COUNTA('Pipeline Rekrutmen'!A4:A200)-1),0) | P5: =IFERROR(AVERAGE('Pipeline Rekrutmen'!P4:P200),0)
B7: ▌ PIPELINE REKRUTMEN PER POSISI
B8: POSISI | C8: DIVISI | D8: PIC HR | E8: STATUS MPR | F8: SOURCING | G8: SCREENING | H8: INTERVIEW HR | I8: INTERVIEW USER | J8: OFFERING | K8: HIRED | L8: REJECTED | M8: WITHDRAW | N8: TOTAL KANDIDAT | O8: TARGET JOIN | P8: SLA TERSISA | Q8: KETERANGAN
B9: HR Staff | C9: Human Resources | D9: Nadira PA | E9: Open | F9: 3 | G9: 2 | H9: 1 | I9: 0 | J9: 0 | K9: 0 | L9: 0 | M9: 3 | N9: 01 Jun 2026 | O9: 25
B10: CX Agent | C10: Customer Experience | D10: Nadira PA | E10: Open | F10: 15 | G10: 8 | H10: 4 | I10: 2 | J10: 1 | K10: 0 | L10: 3 | M10: 15 | N10: 15 May 2026 | O10: 10 | P10: 1 kandidat strong
B11: Backend Dev | C11: Engineering | D11: Nadira PA | E11: Open | F11: 20 | G11: 10 | H11: 5 | I11: 3 | J11: 1 | K11: 1 | L11: 5 | M11: 20 | N11: 01 Jun 2026 | O11: 20 | P11: Technical test done
B12: Data Analyst | C12: Data & Insight | D12: Nadira PA | E12: Hold | F12: 8 | G12: 3 | H12: 1 | I12: 0 | J12: 0 | K12: 0 | L12: 2 | M12: 8 | N12: 01 Jul 2026 | O12: 45 | P12: Budget review
B13: Marketing Lead | C13: Marketing | D13: Nadira PA | E13: Open | F13: 12 | G13: 6 | H13: 3 | I13: 2 | J13: 1 | K13: 0 | L13: 2 | M13: 12 | N13: 15 May 2026 | O13: 8 | P13: Urgent
B16: ▌ RECRUITMENT FUNNEL TRACKER — AKUMULASI SEMUA POSISI AKTIF
B17: TAHAP | C17: JML KANDIDAT | D17: KONVERSI KE TAHAP BERIKUTNYA | E17: BENCHMARK
B18: Sumber / Sourcing | C18: =SUM('Pipeline Rekrutmen'!F4:F200) | D18: 100% (base) | E18: —
B19: Lolos Screening CV | C19: =SUM('Pipeline Rekrutmen'!G4:G200) | D19: =IFERROR(SUM('Pipeline Rekrutmen'!G4:G200)/SUM('Pipeline Rekrutmen'!F4:F200),0) | E19: 40-60%
B20: Interview HR | C20: =SUM('Pipeline Rekrutmen'!H4:H200)+COUNTIF('Pipeline Rekrutmen'!H:H,"Interview HR") | D20: =IFERROR(COUNTIF('Pipeline Rekrutmen'!H:H,"Interview HR")/SUM('Pipeline Rekrutmen'!G4:G200),0) | E20: 60-80%
B21: Interview User/Tech | C21: =COUNTIF('Pipeline Rekrutmen'!H:H,"Interview User") | D21: =IFERROR(COUNTIF('Pipeline Rekrutmen'!H:H,"Interview User")/COUNTIF('Pipeline Rekrutmen'!H:H,"Interview HR"),0) | E21: 50-70%
B22: Offering Stage | C22: =COUNTIF('Pipeline Rekrutmen'!H:H,"Offering") | D22: =IFERROR(COUNTIF('Pipeline Rekrutmen'!H:H,"Offering")/COUNTIF('Pipeline Rekrutmen'!H:H,"Interview User"),0) | E22: 70-90%
B23: HIRED | C23: =COUNTIF('Pipeline Rekrutmen'!H:H,"Hired") | D23: =IFERROR(COUNTIF('Pipeline Rekrutmen'!H:H,"Hired")/COUNTIF('Pipeline Rekrutmen'!H:H,"Offering"),0) | E23: 80-95%

Sheet Pipeline Rekrutmen
A1: RECRUITMENT PIPELINE TRACKER — PT ARUNIKA GROWTH INDONESIA
A2: Gunakan sheet ini sebagai database utama tracking kandidat. Update status setiap ada perkembangan.
A4: NO | B4: NO MPR | C4: POSISI | D4: DIVISI | E4: STATUS MPR | F4: TOTAL SOURCING | G4: LOLOS SCREENING | H4: STAGE SAAT INI | I4: NAMA KANDIDAT | J4: NO HP | K4: EMAIL | L4: TGL SCREENING | M4: TGL INTERVIEW HR | N4: TGL INTERVIEW USER | O4: TGL OFFERING | P4: TIME TO HIRE (HARI) | Q4: EXP GAJI (Rp) | R4: OFFER GAJI (Rp) | S4: STATUS AKHIR | T4: CATATAN
A5: 1 | B5: ARK/MPR/001 | C5: CX Agent | D5: Customer Experience | E5: Open | F5: 15 | G5: 8 | H5: Interview User | I5: Andi Pratama | J5: 081200001111 | K5: andi@email.com | L5: 01/04/26 | M5: 05/04/26 | N5: 10/04/26 | Q5: 4500000 | R5: 5000000 | S5: On Process | T5: Strong candidate
A6: 2 | B6: ARK/MPR/001 | C6: CX Agent | D6: Customer Experience | E6: Open | F6: 15 | G6: 8 | H6: Offering | I6: Rina Sari | J6: 081200002222 | K6: rina@email.com | L6: 01/04/26 | M6: 05/04/26 | N6: 10/04/26 | O6: 15/04/26 | P6: 18 | Q6: 5000000 | R6: 5500000 | S6: Offering | T6: Verbal: setuju
A7: 3 | B7: ARK/MPR/001 | C7: CX Agent | D7: Customer Experience | E7: Open | F7: 15 | G7: 8 | H7: Rejected | I7: Budi Hartono | J7: 081200003333 | K7: budi@email.com | L7: 01/04/26 | Q7: 3800000 | S7: Rejected | T7: Exp gaji tidak sesuai
A8: 4 | B8: ARK/MPR/002 | C8: Backend Dev | D8: Engineering | E8: Open | F8: 20 | G8: 10 | H8: Interview Final | I8: Citra Dewi | J8: 081200004444 | K8: citra@email.com | L8: 03/04/26 | M8: 08/04/26 | N8: 12/04/26 | Q8: 8000000 | R8: 8500000 | S8: On Process | T8: Teknis sangat baik
A9: 5 | B9: ARK/MPR/003 | C9: Marketing Lead | D9: Marketing | E9: Open | F9: 12 | G9: 6 | H9: Interview HR | I9: Fajar Nugroho | J9: 081200005555 | K9: fajar@email.com | L9: 05/04/26 | M9: 10/04/26 | Q9: 9000000 | S9: Screening | T9: Culture fit perlu didalami

Sheet Recruitment Checklist
A1: RECRUITMENT PROCESS CHECKLIST — PT ARUNIKA GROWTH INDONESIA
A2: Gunakan checklist ini untuk setiap proses rekrutmen. Tandai ✓ jika sudah selesai dan isi kolom keterangan.
A4: Posisi: | C4: MPR No.: | E4: PIC HR: | G4: Hiring Mgr: | I4: Tgl Mulai:
A6: ▌ PRE-REKRUTMEN
A7: ✓ | B7: AKTIVITAS / CHECKLIST ITEM | C7: DOKUMEN REFERENSI | D7: PIC | E7: TGL SELESAI | F7: KETERANGAN
A8: ☐ | B8: MPR sudah dibuat dan diisi lengkap oleh Hiring Manager | C8: ARK/HR/REC/F-01 | D8: HR Staff
A9: ☐ | B9: MPR sudah mendapat approval HR Manager & COO | C9: ARK/HR/REC/F-01 | D9: HR Manager
A10: ☐ | B10: Job Description sudah dipersiapkan/diperbarui | C10: JD Template | D10: HR Staff
A11: ☐ | B11: Kualifikasi minimum & kompensasi range sudah dikonfirmasi | C11: MPR | D11: HR Staff
A12: ☐ | B12: Job posting draft sudah di-review Hiring Manager | C12: — | D12: HR Staff
A13: ☐ | B13: Akun job portal sudah aktif dan lowongan dipublish | C13: LinkedIn/Glints/Jobstreet | D13: HR Staff
A14: ☐ | B14: Internal referral program sudah diumumkan ke karyawan | C14: Email Internal | D14: HR Staff
A16: ▌ SOURCING & SCREENING
A17: ✓ | B17: AKTIVITAS / CHECKLIST ITEM | C17: DOKUMEN REFERENSI | D17: PIC | E17: TGL SELESAI | F17: KETERANGAN
A18: ☐ | B18: Sourcing CV dari minimal 2 channel berbeda | C18: Job Portal | D18: HR Staff
A19: ☐ | B19: Candidate pool minimal 5 kandidat per posisi | C19: Pipeline Tracker | D19: HR Staff
A20: ☐ | B20: Screening CV menggunakan Candidate Screening Form | C20: ARK/HR/REC/F-02 | D20: HR Staff
A21: ☐ | B21: Informasi keputusan screening dikomunikasikan ke kandidat | C21: Email/WA | D21: HR Staff
A22: ☐ | B22: Kandidat yang tidak lolos sudah diberi notifikasi | C22: Template Email | D22: HR Staff
A23: ☐ | B23: Kandidat lolos dijadwalkan interview HR | C23: Google Calendar | D23: HR Staff
A25: ▌ INTERVIEW PROCESS
A26: ✓ | B26: AKTIVITAS / CHECKLIST ITEM | C26: DOKUMEN REFERENSI | D26: PIC | E26: TGL SELESAI | F26: KETERANGAN
A27: ☐ | B27: Interview invitation sudah dikirim minimal 2 hari sebelum | C27: Template Email | D27: HR Staff
A28: ☐ | B28: Interview Guide HR disiapkan | C28: ARK/HR/REC/F-04 | D28: HR Staff
A29: ☐ | B29: Interview HR sudah dilaksanakan & dinilai | C29: Assessment Form | D29: HR Staff
A30: ☐ | B30: Hasil interview HR sudah diinfokan ke Hiring Manager | C30: Notif/Email | D30: HR Staff
A31: ☐ | B31: Interview User/Technical sudah dijadwalkan | C31: Google Calendar | D31: HR Staff
A32: ☐ | B32: Interview Assessment Form sudah diisi Interviewer | C32: ARK/HR/REC/F-03 | D32: Hiring Manager
A33: ☐ | B33: Untuk level Senior: Interview Final sudah dilakukan | C33: — | D33: HR Manager/COO
A34: ☐ | B34: Diskusi & keputusan kandidat final sudah disepakati semua pihak | C34: Meeting Notes | D34: HR Staff
A36: ▌ OFFERING & NEGOSIASI
A37: ✓ | B37: AKTIVITAS / CHECKLIST ITEM | C37: DOKUMEN REFERENSI | D37: PIC | E37: TGL SELESAI | F37: KETERANGAN
A38: ☐ | B38: Reference check sudah dilakukan (min. 1 referensi) | C38: — | D38: HR Staff
A39: ☐ | B39: Offering & Negotiation Sheet sudah disiapkan | C39: ARK/HR/REC/F-04 | D39: HR Staff
A40: ☐ | B40: Verbal offer sudah disampaikan ke kandidat | C40: — | D40: HR Staff
A41: ☐ | B41: Offer Letter resmi sudah dibuat & ditandatangani HRD | C41: Offer Letter | D41: HR Manager
A42: ☐ | B42: Offer Letter sudah diterima kandidat (TTD) | C42: Dokumen Fisik | D42: HR Staff
A43: ☐ | B43: Tanggal masuk kerja sudah dikonfirmasi kandidat | C43: — | D43: HR Staff
A45: ▌ PRE-ONBOARDING
A46: ✓ | B46: AKTIVITAS / CHECKLIST ITEM | C46: DOKUMEN REFERENSI | D46: PIC | E46: TGL SELESAI | F46: KETERANGAN
...

Sheet Interview Guide
A1: INTERVIEW GUIDE — BEHAVIORAL & COMPETENCY-BASED
A2: PT Arunika Growth Indonesia | HR Division | Digunakan oleh semua Interviewer
A4: Nama Kandidat: | C4: Posisi: | E4: Tanggal: | G4: Interviewer: | I4: Tipe Interview:
A6: ▌ PEMBUKAAN & RAPPORT BUILDING
A7: NO | B7: TOPIK / PERTANYAAN | C7: PERTANYAAN UTAMA (Wajib diajukan) | D7: METODE | E7: KOMPETENSI DINILAI | F7: 1 | G7: 2 | H7: 3 | I7: 4 | J7: 5
A8: 1 | B8: Pembukaan | C8: Perkenalkan diri dan jelaskan alur interview hari ini. Buat kandidat merasa nyaman. | D8: Waktu: 5 menit | E8: — | F8: ☐ | G8: ☐ | H8: ☐ | I8: ☐ | J8: ☐
A9: 2 | B9: Ice Breaker | C9: Ceritakan perjalanan karir Anda secara singkat dari awal hingga saat ini. | D9: STAR Method | E9: Culture Fit | F9: ☐ | G9: ☐ | H9: ☐ | I9: ☐ | J9: ☐
A10: 3 | B10: Motivasi Melamar | C10: Apa yang membuat Anda tertarik untuk bergabung dengan PT Arunika Growth Indonesia khususnya untuk posisi ini? | D10: Open-ended | E10: Culture Fit | F10: ☐ | G10: ☐ | H10: ☐ | I10: ☐ | J10: ☐
A12: ▌ KOMPETENSI BEHAVIORAL (STAR METHOD)
A13: NO | B13: TOPIK / PERTANYAAN | C13: PERTANYAAN UTAMA (Wajib diajukan) | D13: METODE | E13: KOMPETENSI DINILAI | F13: 1 | G13: 2 | H13: 3 | I13: 4 | J13: 5
A14: 1 | B14: Teamwork | C14: Ceritakan satu pengalaman di mana Anda harus bekerja dalam tim yang memiliki perbedaan pendapat tajam. Bagaimana Anda mengelolanya dan apa hasilnya? | D14: STAR | E14: Teamwork | F14: ☐ | G14: ☐ | H14: ☐ | I14: ☐ | J14: ☐
A15: 2 | B15: Problem Solving | C15: Ceritakan situasi di mana Anda menghadapi masalah yang sangat kompleks dan tidak ada solusi yang jelas. Apa yang Anda lakukan? | D15: STAR | E15: Problem Solving | F15: ☐ | G15: ☐ | H15: ☐ | I15: ☐ | J15: ☐
A16: 3 | B16: Adaptabilitas | C16: Berikan contoh ketika Anda harus beradaptasi dengan perubahan besar dalam pekerjaan atau lingkungan kerja. Bagaimana respons Anda? | D16: STAR | E16: Adaptability | F16: ☐ | G16: ☐ | H16: ☐ | I16: ☐ | J16: ☐
A17: 4 | B17: Inisiatif | C17: Ceritakan saat Anda mengambil inisiatif tanpa diminta atasan dan memberikan dampak positif. | D17: STAR | E17: Initiative | F17: ☐ | G17: ☐ | H17: ☐ | I17: ☐ | J17: ☐
A18: 5 | B18: Handling Pressure | C18: Bagaimana Anda mengelola situasi ketika Anda memiliki beberapa deadline bersamaan dan sumber daya terbatas? | D18: STAR | E18: Stress Mgmt | F18: ☐ | G18: ☐ | H18: ☐ | I18: ☐ | J18: ☐
A19: 6 | B19: Leadership (Mid-Senior) | C19: Ceritakan pengalaman Anda memimpin tim melewati tantangan atau target yang ambisius. | D19: STAR (Senior only) | E19: Leadership | F19: ☐ | G19: ☐ | H19: ☐ | I19: ☐ | J19: ☐
A21: ▌ MOTIVASI & CULTURE FIT
A22: NO | B22: TOPIK / PERTANYAAN | C22: PERTANYAAN UTAMA (Wajib diajukan) | D22: METODE | E22: KOMPETENSI DINILAI | F22: 1 | G22: 2 | H22: 3 | I22: 4 | J22: 5
A23: 1 | B23: Value Perusahaan | C23: Apa nilai atau prinsip kerja yang paling penting bagi Anda? Bagaimana nilai tersebut tercermin dalam cara kerja Anda sehari-hari? | D23: Open-ended | E23: Values Alignment | F23: ☐ | G23: ☐ | H23: ☐ | I23: ☐ | J23: ☐
A24: 2 | B24: Career Goals | C24: Di mana Anda melihat karir Anda dalam 3-5 tahun ke depan? Bagaimana posisi ini mendukung tujuan tersebut? | D24: Funnel probing | E24: Ambition | F24: ☐ | G24: ☐ | H24: ☐ | I24: ☐ | J24: ☐
A25: 3 | B25: Fast-Paced Env | C25: Arunika adalah startup yang bergerak cepat. Bagaimana pengalaman Anda bekerja di lingkungan yang dinamis dan sering berubah? | D25: Open-ended | E25: Culture Fit | F25: ☐ | G25: ☐ | H25: ☐ | I25: ☐ | J25: ☐
A26: 4 | B26: Work Style | C26: Bagaimana gaya kerja ideal Anda — lebih suka bekerja mandiri atau dalam tim? Berikan contoh nyata. | D26: Open-ended | E26: Culture Fit | F26: ☐ | G26: ☐ | H26: ☐ | I26: ☐ | J26: ☐
A28: ▌ TECHNICAL / ROLE-SPECIFIC
A29: NO | B29: TOPIK / PERTANYAAN | C29: PERTANYAAN UTAMA (Wajib diajukan) | D29: METODE | E29: KOMPETENSI DINILAI | F29: 1 | G29: 2 | H29: 3 | I29: 4 | J29: 5
A30: 1 | B30: Technical Knowledge | C30: Jelaskan pengalaman Anda yang paling relevan dengan tanggung jawab utama posisi ini. | D30: Probe deep | E30: Hard Skill | F30: ☐ | G30: ☐ | H30: ☐ | I30: ☐ | J30: ☐
A31: 2 | B31: Tools & System | C31: Tools, sistem, atau teknologi apa saja yang Anda kuasai dan paling sering Anda gunakan? | D31: Knowledge check | E31: Technical | F31: ☐ | G31: ☐ | H31: ☐ | I31: ☐ | J31: ☐
A32: 3 | B32: Case Study | C32: (Opsional) Berikan case study singkat sesuai posisi — kandidat diminta analisis dan saran solusi. | D32: Case/Scenario | E32: Analytical | F32: ☐ | G32: ☐ | H32: ☐ | I32: ☐ | J32: ☐
A34: ▌ PENUTUP
A35: NO | B35: TOPIK / PERTANYAAN | C35: PERTANYAAN UTAMA (Wajib diajukan) | D35: METODE | E35: KOMPETENSI DINILAI | F35: 1 | G35: 2 | H35: 3 | I35: 4 | J35: 5
A36: 1 | B36: Pertanyaan Balik | C36: Apakah ada pertanyaan dari Anda tentang posisi, tim, atau perusahaan? | D36: Reflektif | E36: Curiosity | F36: ☐ | G36: ☐ | H36: ☐ | I36: ☐ | J36: ☐
A37: 2 | B37: Kompensasi | C37: Berapa ekspektasi gaji Anda? Apakah ada benefit khusus yang menjadi prioritas? | D37: Direct | E37: Expectation | F37: ☐ | G37: ☐ | H37: ☐ | I37: ☐ | J37: ☐
A38: 3 | B38: Closing | C38: Jelaskan next step proses rekrutmen, timeline, dan cara komunikasi selanjutnya. | D38: Waktu: 5 menit | E38: — | F38: ☐ | G38: ☐ | H38: ☐ | I38: ☐ | J38: ☐
A40: ▌ SKALA PENILAIAN | 1 = Tidak Memenuhi | 2 = Perlu Pengembangan | 3 = Memenuhi Standar | 4 = Melebihi Standar | 5 = Sangat Unggul

Sheet Template Email
A1: TEMPLATE EMAIL REKRUTMEN — PT ARUNIKA GROWTH INDONESIA
A2: Ganti teks dalam [TANDA KURUNG] dengan informasi yang relevan sebelum mengirim.
A4: ▌ TEMPLATE EMAIL 01 — UNDANGAN INTERVIEW HR
A5: SUBJECT: | B5: Subject: Undangan Interview | [NAMA POSISI] — PT Arunika Growth Indonesia
A6: BODY EMAIL: | B6: Yth. Bapak/Ibu [NAMA KANDIDAT], Terima kasih atas ketertarikan Anda pada posisi [NAMA POSISI] di PT Arunika Growth Indonesia. Setelah melalui proses seleksi administrasi, kami dengan senang hati mengundang Anda untuk mengikuti tahap Interview HR bersama tim kami. Detail Interview: • Tanggal : [HARI, TANGGAL] • Waktu : [JAM] WIB • Format : [Video Call via Google Meet / Telepon] • Link Meet: [LINK GOOGLE MEET] (jika video call) • Estimasi Durasi: 30-45 menit Mohon konfirmasi kehadiran Anda paling lambat [TANGGAL KONFIRMASI] melalui email ini atau WhatsApp ke [NOMOR HR]. Jika ada kendala jadwal, jangan ragu untuk menghubungi kami dan kami akan carikan waktu alternatif yang sesuai. Kami menantikan kesempatan untuk mengenal Anda lebih jauh. Salam hangat, [NAMA HR STAFF] Human Resources | PT Arunika Growth Indonesia hr@arunikagrowth.co.id | (021) 5000-9988
A24: ▌ TEMPLATE EMAIL 02 — UNDANGAN INTERVIEW USER/TECHNICAL
A25: SUBJECT: | B25: Subject: Undangan Interview Tahap Lanjut | [NAMA POSISI] — PT Arunika Growth Indonesia
A26: BODY EMAIL: | B26: Yth. Bapak/Ibu [NAMA KANDIDAT], Selamat! Anda berhasil melanjutkan ke tahap Interview User/Technical untuk posisi [NAMA POSISI] di PT Arunika Growth Indonesia. Detail Interview: • Tanggal : [HARI, TANGGAL] • Waktu : [JAM] WIB • Format : [Video Call / Onsite di Kantor] • Alamat : Jl. Sudirman Kav. 52-53, Jakarta Selatan (jika onsite) • Interviewer: [NAMA INTERVIEWER], [JABATAN] [Jika ada Technical Test:] Anda akan diminta mengerjakan Technical Assessment singkat (~60 menit) sebelum/sesudah sesi interview. Topik: [DESKRIPSI SINGKAT TOPIK TEST] Harap membawa: • Identitas diri (KTP/SIM) • Laptop (jika diperlukan untuk test) • Portofolio/hasil kerja relevan (opsional) Mohon konfirmasi kehadiran melalui email ini. Salam, [NAMA HR STAFF] Human Resources | PT Arunika Growth Indonesia
A44: ▌ TEMPLATE EMAIL 03 — PENOLAKAN (TIDAK LOLOS SCREENING)
A45: SUBJECT: | B45: Subject: Pemberitahuan Hasil Seleksi | [NAMA POSISI] — PT Arunika Growth Indonesia
A46: BODY EMAIL: | B46: Yth. Bapak/Ibu [NAMA KANDIDAT], Terima kasih atas waktu dan ketertarikan Anda untuk berkarir bersama PT Arunika Growth Indonesia melalui lamaran posisi [NAMA POSISI]. Setelah melalui proses evaluasi yang cermat, dengan penuh pertimbangan kami menyampaikan bahwa pada kesempatan ini kami belum dapat melanjutkan proses seleksi Anda ke tahap berikutnya. Keputusan ini tidak serta-merta mencerminkan kualitas Anda sebagai profesional. Kami mendorong Anda untuk terus mengembangkan diri dan tidak menutup kemungkinan untuk melamar posisi lain yang mungkin lebih sesuai di masa mendatang. Profil Anda akan kami simpan dalam database talent pool kami dan kami akan menghubungi Anda jika ada posisi yang lebih sesuai ke depannya. Terima kasih sekali lagi atas waktu yang Anda berikan. Kami mendoakan yang terbaik untuk perjalanan karir Anda. Salam, [NAMA HR STAFF] Human Resources | PT Arunika Growth Indonesia
A64: ▌ TEMPLATE EMAIL 04 — VERBAL OFFER
A65: SUBJECT: | B65: Subject: Penawaran Kerja — [NAMA POSISI] | PT Arunika Growth Indonesia
A66: BODY EMAIL: | B66: Yth. Bapak/Ibu [NAMA KANDIDAT], Selamat! Kami dengan bangga menyampaikan bahwa Anda telah berhasil melalui seluruh tahapan seleksi posisi [NAMA POSISI] di PT Arunika Growth Indonesia. Sesuai diskusi kita sebelumnya, berikut rangkuman penawaran kompensasi yang kami tawarkan: • Gaji Pokok : Rp [NOMINAL]/bulan • Tunjangan Tetap: Rp [NOMINAL]/bulan • Total Package : Rp [TOTAL]/bulan • Tipe Kontrak : [PKWT/PKWTT] — [DURASI jika PKWT] • Target Join : [TANGGAL] • Masa Probasi : [DURASI] Benefit tambahan: • BPJS Ketenagakerjaan & Kesehatan (ditanggung perusahaan) • Laptop kerja disediakan • Cuti tahunan 12 hari • [BENEFIT LAIN SESUAI POSISI] Offer Letter resmi akan kami kirimkan dalam 1x24 jam. Kami memberikan waktu hingga [TANGGAL DEADLINE] untuk memberikan keputusan Anda secara tertulis. Jika ada pertanyaan mengenai detail penawaran, jangan ragu menghubungi kami. Kami sangat antusias untuk segera menyambut Anda bergabung bersama tim Arunika! Salam hangat, [NAMA HR STAFF] Human Resources | PT Arunika Growth Indonesia
A84: ▌ TEMPLATE EMAIL 05 — WELCOME EMAIL (PRE-ONBOARDING)
A85: SUBJECT: | B85: Subject: Selamat Bergabung! Persiapan Hari Pertama Kerja — PT Arunika Growth Indonesia
A86: BODY EMAIL: | B86: Halo [NAMA KARYAWAN BARU], Selamat datang di keluarga besar PT Arunika Growth Indonesia! Kami sangat senang dan antusias menyambut kehadiran Anda sebagai [NAMA POSISI] di tim [NAMA DIVISI], mulai [TANGGAL PERTAMA KERJA]. PERSIAPAN HARI PERTAMA: • Waktu Tiba : Pukul [JAM] WIB • Lokasi : Jl. Sudirman Kav. 52-53, Jakarta Selatan (Lantai [X]) • Dress Code : Smart casual / Business casual • Buddy Anda : [NAMA BUDDY], [JABATAN] — akan menemani hari pertama Anda DOKUMEN YANG PERLU DIBAWA: □ KTP/Identitas diri (asli + fotokopi 2 lembar) □ NPWP (jika ada) □ Ijazah terakhir + transkrip nilai (asli + fotokopi) □ Buku Tabungan (untuk setup payroll) □ Pas foto 3x4 (2 lembar, latar merah) □ Surat Keterangan Sehat dari dokter □ Kartu BPJS (jika sudah memiliki) AGENDA HARI PERTAMA: [JAM] - Welcome & pengenalan dengan HR [JAM] - Orientasi perusahaan & kultur Arunika [JAM] - Setup workstation, email, dan tools [JAM] - Meet the team & makan siang bersama [JAM] - Sesi briefing dengan [NAMA HIRING MANAGER] Jika ada yang ingin ditanyakan sebelum hari H, feel free to reach out! Can't wait to have you on board! Salam hangat, [NAMA HR STAFF] Human Resources | PT Arunika Growth Indonesia hr@arunikagrowth.co.id | (021) 5000-9988
